<?xml version="1.0"?>
<robot name="self_docking_robot" xmlns:xacro="http://www.ros.org/wiki/xacro">

  <xacro:property name="base_length"   value="0.20"/>
  <xacro:property name="base_width"    value="0.15"/>
  <xacro:property name="base_height"   value="0.08"/>
  <xacro:property name="wheel_radius"  value="0.0325"/>
  <xacro:property name="wheel_width"   value="0.025"/>
  <xacro:property name="wheel_sep"     value="0.20"/>

  <!-- Base link -->
  <link name="base_link">
    <visual>
      <geometry><box size="${base_length} ${base_width} ${base_height}"/></geometry>
      <material name="blue"><color rgba="0.2 0.3 0.8 1"/></material>
    </visual>
    <collision>
      <geometry><box size="${base_length} ${base_width} ${base_height}"/></geometry>
    </collision>
    <inertial>
      <mass value="1.5"/>
      <inertia ixx="0.005" iyy="0.007" izz="0.010" ixy="0" ixz="0" iyz="0"/>
    </inertial>
  </link>

  <!-- Left wheel -->
  <xacro:macro name="wheel" params="name y_offset">
    <link name="${name}_wheel">
      <visual>
        <geometry><cylinder radius="${wheel_radius}" length="${wheel_width}"/></geometry>
        <material name="black"><color rgba="0.1 0.1 0.1 1"/></material>
      </visual>
      <collision>
        <geometry><cylinder radius="${wheel_radius}" length="${wheel_width}"/></geometry>
      </collision>
      <inertial>
        <mass value="0.15"/>
        <inertia ixx="0.0001" iyy="0.0001" izz="0.0002" ixy="0" ixz="0" iyz="0"/>
      </inertial>
    </link>
    <joint name="${name}_wheel_joint" type="continuous">
      <parent link="base_link"/>
      <child link="${name}_wheel"/>
      <origin xyz="0 ${y_offset} -0.01" rpy="${pi/2} 0 0"/>
      <axis xyz="0 0 1"/>
    </joint>
  </xacro:macro>

  <xacro:wheel name="left"  y_offset="${ wheel_sep/2}"/>
  <xacro:wheel name="right" y_offset="${-wheel_sep/2}"/>

  <!-- Caster wheel -->
  <link name="caster_wheel">
    <visual>
      <geometry><sphere radius="0.02"/></geometry>
      <material name="grey"><color rgba="0.5 0.5 0.5 1"/></material>
    </visual>
    <collision><geometry><sphere radius="0.02"/></geometry></collision>
    <inertial><mass value="0.05"/>
      <inertia ixx="0.00001" iyy="0.00001" izz="0.00001" ixy="0" ixz="0" iyz="0"/>
    </inertial>
  </link>
  <joint name="caster_joint" type="fixed">
    <parent link="base_link"/><child link="caster_wheel"/>
    <origin xyz="${-base_length/2 + 0.02} 0 ${-wheel_radius}"/>
  </joint>

  <!-- Camera -->
  <link name="camera_link">
    <visual><geometry><box size="0.03 0.09 0.03"/></geometry>
      <material name="grey"><color rgba="0.4 0.4 0.4 1"/></material>
    </visual>
  </link>
  <joint name="camera_joint" type="fixed">
    <parent link="base_link"/><child link="camera_link"/>
    <origin xyz="${base_length/2 - 0.01} 0 ${base_height/2 + 0.015}"/>
  </joint>

  <!-- Laser (lidar) -->
  <link name="laser_link">
    <visual><geometry><cylinder radius="0.04" length="0.04"/></geometry>
      <material name="red"><color rgba="0.8 0.1 0.1 1"/></material>
    </visual>
  </link>
  <joint name="laser_joint" type="fixed">
    <parent link="base_link"/><child link="laser_link"/>
    <origin xyz="0 0 ${base_height/2 + 0.02}"/>
  </joint>

  <!-- ros2_control hardware interface -->
  <ros2_control name="GazeboSystem" type="system">
    <hardware>
      <plugin>gazebo_ros2_control/GazeboSystem</plugin>
    </hardware>
    <joint name="left_wheel_joint">
      <command_interface name="velocity"/>
      <state_interface name="velocity"/>
      <state_interface name="position"/>
    </joint>
    <joint name="right_wheel_joint">
      <command_interface name="velocity"/>
      <state_interface name="velocity"/>
      <state_interface name="position"/>
    </joint>
  </ros2_control>

  <!-- Gazebo plugins -->
  <gazebo>
    <plugin name="gazebo_ros2_control" filename="libgazebo_ros2_control.so">
      <parameters>$(find robot_bringup)/config/ros2_controllers.yaml</parameters>
    </plugin>
  </gazebo>
  <gazebo reference="laser_link">
    <sensor name="laser" type="ray">
      <pose>0 0 0 0 0 0</pose>
      <ray>
        <scan><horizontal><samples>360</samples><min_angle>-3.14159</min_angle><max_angle>3.14159</max_angle></horizontal></scan>
        <range><min>0.1</min><max>12.0</max></range>
      </ray>
      <update_rate>10</update_rate>
      <plugin name="laser_plugin" filename="libgazebo_ros_ray_sensor.so">
        <ros><remapping>~/out:=scan</remapping></ros>
        <output_type>sensor_msgs/LaserScan</output_type>
        <frame_name>laser_link</frame_name>
      </plugin>
    </sensor>
  </gazebo>
</robot>
